<?xml version="1.0"?>
<robot xmlns:xacro="http://www.ros.org/wiki/xacro" name="dtw_robot">
	<material name="gray">
		<color rgba="0.5 0.5 0.5 2.5" />
	</material>
	<material name="red">
		<color rgba="1.0 0.0 0.0 2.5" />
	</material>
	<!--  -->
	<macro name="wheel_macro" params="parent prefix xyz">
		<joint name="${prefix}_joint" type="continuous">
			<origin xyz="${xyz}" rpy="${radians(-90)} 0.0 0.0" />
			<parent link="${parent}" />
			<child link="${prefix}_link" />
			<axis xyz="0 0 1" />
			<limit velocity="12.0" effort="0.4" />
			<dynamics damping="0.1" />
		</joint>
		<transmission name="${prefix}_trans">
			<type>
				transmission_interface/SimpleTransmission
			</type>
			<joint name="${prefix}_joint">
				<hardwareInterface>
					hardware_interface/VelocityJointInterface
				</hardwareInterface>
			</joint>
			<actuator name="${prefix}_motor">
				<hardwareInterface>
					hardware_interface/VelocityJointInterface
				</hardwareInterface>
				<mechanismReduction>
					1
				</mechanismReduction>
			</actuator>
		</transmission>
		<link name="${prefix}_link">
			<inertial>
				<origin xyz="0.0 0.0 0.0" rpy="0.0 0.0 0.0" />
				<mass value="0.5" />
				<inertia ixx="0.0001" ixy="0.0" ixz="0.0" iyy="0.0001" iyz="0.0" izz="0.0001" />
			</inertial>
			<visual>
				<geometry>
					<cylinder radius="0.2" length="0.1" />
				</geometry>
				<material name="red" />
			</visual>
			<collision>
				<geometry>
					<cylinder radius="0.2" length="0.1" />
				</geometry>
			</collision>
		</link>
		<gazebo reference="${prefix}_link">
			<material>
				Gazebo/Red
			</material>
			<mu1 value="2.5" />
			<mu2 value="2.5" />
			<kp value="50000" />
			<kd value="10" />
		</gazebo>
	</macro>
	<!--  -->
	<!--  -->
	<macro name="body_macro" params="parent">
		<joint name="body_joint" type="fixed">
			<parent link="${parent}" />
			<child link="body_link" />
			<origin xyz="0 0 0.4" rpy="0.0 0.0 0.0" />
		</joint>
		<link name="body_link">
			<inertial>
				<origin xyz="0.0 0.0 0.0" rpy="0.0 0.0 0.0" />
				<mass value="1.0" />
				<inertia ixx="0.001" ixy="0.0" ixz="0.0" iyy="0.001" iyz="0.0" izz="0.001" />
			</inertial>
			<visual>
				<origin xyz="0.0 0.0 0.0" rpy="0.0 0.0 0.0" />
				<geometry>
					<box size="0.6 0.40 0.6" />
				</geometry>
				<material name="gray" />
			</visual>
			<collision>
				<origin xyz="0.0 0.0 0.0" rpy="0.0 0.0 0.0" />
				<geometry>
					<box size="0.6 0.40 0.6" />
				</geometry>
			</collision>
		</link>
		<gazebo reference="body_link">
			<material>
				Gazebo/Gray
			</material>
		</gazebo>
		<!--  -->
		<!--  -->
		<joint name="ball_joint" type="fixed">
			<parent link="${parent}" />
			<child link="ball_link" />
			<origin xyz="-0.14 0 0.1" rpy="0.0 0.0 0.0" />
		</joint>
		<link name="ball_link">
			<visual>
				<origin xyz="0.0 0.0 0.0" rpy="0.0 0.0 0.0" />
				<geometry>
					<sphere radius="0.1" />
				</geometry>
				<material name="gray" />
			</visual>
			<collision>
				<origin xyz="0.0 0.0 0.0" rpy="0.0 0.0 0.0" />
				<geometry>
					<sphere radius="0.1" />
				</geometry>
				<material name="gray" />
			</collision>
		</link>
		<gazebo reference="ball_link">
			<material>
				Gazebo/Gray
			</material>
			<mu1 value="0.5" />
			<mu2 value="0.5" />
		</gazebo>
	</macro>
</robot>
